<?xml version="1.0" ?>
<robot name="differential-mobile-robot">

<material name="silver">
  <color rgba="0.700 0.700 0.700 1.000"/>
</material>

<link name="base_link">
  <inertial>
    <origin xyz="-1.2819099005420782e-15 0.0 0.0075000000002764635" rpy="0 0 0"/>
    <mass value="0.6230822460961448"/>
    <inertia ixx="0.00024678249724136556" iyy="0.00031026758160746686" izz="0.0005337374783177649" ixy="1.7848833522293714e-19" iyz="0.0" ixz="7.808864643921406e-20"/>
  </inertial>
  <visual>
    <origin xyz="0 0 0" rpy="0 0 0"/>
    <geometry>
      <mesh filename="meshes/base_link.stl" scale="0.001 0.001 0.001"/>
    </geometry>
    <material name="silver"/>
    <material/>
  </visual>
  <collision>
    <origin xyz="0 0 0" rpy="0 0 0"/>
    <geometry>
      <mesh filename="meshes/base_link.stl" scale="0.001 0.001 0.001"/>
    </geometry>
  </collision>
</link>

<link name="Wheel2_1_1">
  <inertial>
    <origin xyz="-7.977024924141525e-15 -0.0025000000000000022 1.1175874375241035e-10" rpy="0 0 0"/>
    <mass value="0.025154733126962883"/>
    <inertia ixx="1.4139056653204502e-06" iyy="2.7229999423009313e-06" izz="1.4139056650095078e-06" ixy="-5.229150445990025e-22" iyz="-8.470329472543003e-22" ixz="-1.5202883620880588e-18"/>
  </inertial>
  <visual>
    <origin xyz="-0.0 -0.04 -0.0075" rpy="0 0 0"/>
    <geometry>
      <mesh filename="meshes/Wheel2_1_1.stl" scale="0.001 0.001 0.001"/>
    </geometry>
    <material name="silver"/>
    <material/>
  </visual>
  <collision>
    <origin xyz="-0.0 -0.04 -0.0075" rpy="0 0 0"/>
    <geometry>
      <mesh filename="meshes/Wheel2_1_1.stl" scale="0.001 0.001 0.001"/>
    </geometry>
  </collision>
</link>

<link name="Wheel1_1_1">
  <inertial>
    <origin xyz="-8.00474217544153e-15 0.0025000000000000022 1.1175871166002604e-10" rpy="0 0 0"/>
    <mass value="0.025154733126962883"/>
    <inertia ixx="1.4139056653204502e-06" iyy="2.7229999423009305e-06" izz="1.4139056650094942e-06" ixy="1.045830089198005e-21" iyz="8.470329472543003e-22" ixz="2.0916376749779306e-21"/>
  </inertial>
  <visual>
    <origin xyz="-0.0 0.04 -0.0075" rpy="0 0 0"/>
    <geometry>
      <mesh filename="meshes/Wheel1_1_1.stl" scale="0.001 0.001 0.001"/>
    </geometry>
    <material name="silver"/>
    <material/>
  </visual>
  <collision>
    <origin xyz="-0.0 0.04 -0.0075" rpy="0 0 0"/>
    <geometry>
      <mesh filename="meshes/Wheel1_1_1.stl" scale="0.001 0.001 0.001"/>
    </geometry>
  </collision>
</link>

<link name="Camera_1_1">
  <inertial>
    <origin xyz="0.030000000000000006 -4.440892098500626e-18 0.0025000000000000022" rpy="0 0 0"/>
    <mass value="0.0058874999999999995"/>
    <inertia ixx="1.226562499999998e-07" iyy="6.132812500000001e-08" izz="1.5945312499999833e-07" ixy="-3.48610029732299e-23" iyz="-2.1788126858268794e-23" ixz="1.2705494208814505e-21"/>
  </inertial>
  <visual>
    <origin xyz="-0.0 0.0 -0.015" rpy="0 0 0"/>
    <geometry>
      <mesh filename="meshes/Camera_1_1.stl" scale="0.001 0.001 0.001"/>
    </geometry>
    <material name="silver"/>
    <material/>
  </visual>
  <collision>
    <origin xyz="-0.0 0.0 -0.015" rpy="0 0 0"/>
    <geometry>
      <mesh filename="meshes/Camera_1_1.stl" scale="0.001 0.001 0.001"/>
    </geometry>
  </collision>
</link>

<joint name="Revolute 4" type="continuous">
  <origin xyz="0.0 0.04 0.0075" rpy="0 0 0"/>
  <parent link="base_link"/>
  <child link="Wheel2_1_1"/>
  <axis xyz="0.0 1.0 0.0"/>
</joint>
<transmission name="Revolute 4_tran">
  <type>transmission_interface/SimpleTransmission</type>
  <joint name="Revolute 4">
    <hardwareInterface>PositionJointInterface</hardwareInterface>
  </joint>
  <actuator name="Revolute 4_actr">
    <hardwareInterface>PositionJointInterface</hardwareInterface>
    <mechanicalReduction>1</mechanicalReduction>
  </actuator>
</transmission>

<joint name="Revolute 5" type="continuous">
  <origin xyz="0.0 -0.04 0.0075" rpy="0 0 0"/>
  <parent link="base_link"/>
  <child link="Wheel1_1_1"/>
  <axis xyz="0.0 -1.0 0.0"/>
</joint>
<transmission name="Revolute 5_tran">
  <type>transmission_interface/SimpleTransmission</type>
  <joint name="Revolute 5">
    <hardwareInterface>PositionJointInterface</hardwareInterface>
  </joint>
  <actuator name="Revolute 5_actr">
    <hardwareInterface>PositionJointInterface</hardwareInterface>
    <mechanicalReduction>1</mechanicalReduction>
  </actuator>
</transmission>

<joint name="Rigid 6" type="fixed">
  <origin xyz="0.0 0.0 0.015" rpy="0 0 0"/>
  <parent link="base_link"/>
  <child link="Camera_1_1"/>
</joint>

</robot>
