#VRML_SIM R2025a utf8

EXTERNPROTO "https://raw.githubusercontent.com/cyberbotics/webots/R2025a/projects/objects/backgrounds/protos/TexturedBackground.proto"
EXTERNPROTO "https://raw.githubusercontent.com/cyberbotics/webots/R2025a/projects/objects/backgrounds/protos/TexturedBackgroundLight.proto"
EXTERNPROTO "https://raw.githubusercontent.com/cyberbotics/webots/R2025a/projects/objects/floors/protos/RectangleArena.proto"
EXTERNPROTO "https://raw.githubusercontent.com/cyberbotics/webots/R2025a/projects/appearances/protos/Parquetry.proto"

WorldInfo {
}
Viewpoint {
  orientation 0.11242452528318134 -0.12034981145371337 -0.9863450963014451 4.76670973585195
  position 0.1762401190372147 -7.608697447855719 1.4043772014101714
  follow "robot"
}
TexturedBackground {
}
TexturedBackgroundLight {
}
RectangleArena {
  floorSize 3 3
  floorAppearance Parquetry {
    type "dark strip"
  }
}
DEF MARS_HELICOPTER Robot {
  translation 0 0 0.045
  children [
    Transform {
      scale 0.01 0.01 0.01
      children [
        Shape {
          appearance PBRAppearance {
            baseColor 1 0.5 0.4
            roughness 0.25
            emissiveColor 0.8 0.3 0.1
          }
          geometry Mesh {
            url [
              "../meshes/Body.obj"
            ]
          }
        }
      ]
    }
    DEF HEIGHT_SENSOR_MOUNT Solid {
      translation 0 0 0.0025
      rotation 0 1 0 1.57
      children [
        DistanceSensor {
          name "height sensor"
          lookupTable [
            0 0 0
            10 10 0
          ]
          type "infra-red"
          numberOfRays 5
          aperture 0.2
          gaussianWidth 0.5
          resolution 0.001
        }
      ]
      boundingObject Sphere {
        radius 0.01
      }
      physics Physics {
        density -1
        mass 0.001
      }
    }
    HingeJoint {
      jointParameters HingeJointParameters {
        axis 0 0 1
        anchor 0 0 0.12
      }
      device [
        RotationalMotor {
          name "motor top"
          maxVelocity 100
        }
      ]
      endPoint DEF ROTOR_TOP_CW Solid {
        translation 0 0 0.12
        children [
          Transform {
            scale 0.01 0.01 0.01
            children [
              Shape {
                appearance PBRAppearance {
                  baseColor 0.5 0.5 0.5
                  roughness 1
                  metalness 0
                }
                geometry Mesh {
                  url [
                    "../meshes/Propeller.obj"
                  ]
                }
              }
            ]
          }
        ]
        name "rotor top cw(1)"
        boundingObject Pose {
          translation 0 0 0.0025
          children [
            Cylinder {
              height 0.005
              radius 0.2
            }
          ]
        }
        physics Physics {
          density -1
          mass 0.025
        }
      }
    }
    HingeJoint {
      jointParameters HingeJointParameters {
        axis 0 0 -1
        anchor 0 0 0.11
      }
      device [
        RotationalMotor {
          name "motor bottom"
          maxVelocity 100
        }
      ]
      endPoint DEF ROTOR_BOTTOM_CCW Solid {
        translation 0 0 0.11
        rotation 0 0 1 1.5700000000000087
        children [
          Transform {
            scale 0.01 0.01 0.01
            children [
              Shape {
                appearance PBRAppearance {
                  baseColor 0.5 0.5 0.5
                  roughness 1
                  metalness 0
                }
                geometry Mesh {
                  url [
                    "../meshes/Propeller.obj"
                  ]
                }
              }
            ]
          }
        ]
        name "rotor bottom ccw"
        boundingObject Pose {
          translation 0 0 0.0025
          children [
            Cylinder {
              height 0.005
              radius 0.2
            }
          ]
        }
        physics Physics {
          density -1
          mass 0.025
        }
      }
    }
  ]
  boundingObject Pose {
    translation 0 0 0.04
    children [
      Box {
        size 0.1 0.1 0.17
      }
    ]
  }
  physics Physics {
    density -1
    mass 0.45
  }
  controller "altitude_control"
  supervisor TRUE
}
