#VRML_SIM R2025a utf8

EXTERNPROTO "https://raw.githubusercontent.com/cyberbotics/webots/R2025a/projects/objects/backgrounds/protos/TexturedBackground.proto"
EXTERNPROTO "https://raw.githubusercontent.com/cyberbotics/webots/R2025a/projects/objects/backgrounds/protos/TexturedBackgroundLight.proto"
EXTERNPROTO "https://raw.githubusercontent.com/cyberbotics/webots/R2025a/projects/objects/floors/protos/RectangleArena.proto"
EXTERNPROTO "https://raw.githubusercontent.com/cyberbotics/webots/R2025a/projects/appearances/protos/Parquetry.proto"

WorldInfo {
}
Viewpoint {
  orientation -0.18472061403818274 0.18657934656317254 0.9649178421945654 1.596509014371246
  position 0.016640454896317172 -1.0261456613743016 0.406774867517056
  follow "quadcopter"
}
TexturedBackground {
}
TexturedBackgroundLight {
}
RectangleArena {
  floorSize 2 2
  floorAppearance Parquetry {
  }
  wallHeight 0.03
}
DEF QUADCOPTER Robot {
  children [
    GPS {
      translation 0.05 0 0.055
      children [
        Transform {
          translation 0 0 -0.02
          scale 0.01 0.01 0.01
          children [
            Shape {
              appearance PBRAppearance {
                baseColor 0.6 0.6 0.6
                roughness 1
                metalness 0
              }
              geometry Mesh {
                url [
                  "../meshes/gps.obj"
                ]
              }
            }
          ]
        }
      ]
      boundingObject Cylinder {
        height 0.03
        radius 0.025
      }
      physics Physics {
        density -1
        mass 0.07
      }
      accuracy 1
      noiseCorrelation 0.8
      resolution 0.01
      speedNoise 0.2
      speedResolution 0.05
    }
    Transform {
      translation 0 0 0.03
      scale 0.01 0.01 0.01
      children [
        Shape {
          appearance PBRAppearance {
            baseColor 0.8 0.8 0
            roughness 1
          }
          geometry Mesh {
            url [
              "../meshes/body.obj"
            ]
          }
        }
      ]
    }
    InertialUnit {
      translation 0 0 0.045
      rotation 0 0 1 3.14
      children [
        Shape {
          appearance PBRAppearance {
            baseColor 0.6 0.8 0.3
            roughness 1
            metalness 0
          }
          geometry Box {
            size 0.02 0.02 0.005
          }
        }
      ]
      name "imu"
      boundingObject Box {
        size 0.02 0.02 0.005
      }
      physics Physics {
        density -1
        mass 0.03
      }
      noise 0.005
      resolution 0.001
    }
    DEF prop1 HingeJoint {
      jointParameters HingeJointParameters {
        axis 0 0 1
        anchor -0.1 -0.1 0.047
      }
      device [
        RotationalMotor {
          name "motor 1"
          maxVelocity 100
        }
      ]
      endPoint Solid {
        translation -0.1 -0.1 0.047
        children [
          Transform {
            scale 0.01 0.01 0.01
            children [
              Shape {
                appearance PBRAppearance {
                  baseColor 0.75 0.75 0.75
                  roughness 1
                  metalness 0
                }
                geometry Mesh {
                  url [
                    "../meshes/Prop_ccw.obj"
                  ]
                }
              }
            ]
          }
        ]
        name "prop1ccw"
        boundingObject Pose {
          translation 0 0 0.0025
          children [
            Cylinder {
              height 0.005
              radius 0.055
            }
          ]
        }
        physics Physics {
          density -1
          mass 0.02
        }
      }
    }
    DEF prop3 HingeJoint {
      jointParameters HingeJointParameters {
        axis 0 0 1
        anchor 0.1 0.1 0.047
      }
      device [
        RotationalMotor {
          name "motor 3"
          maxVelocity 100
        }
      ]
      endPoint Solid {
        translation 0.1 0.1 0.047
        children [
          Transform {
            scale 0.01 0.01 0.01
            children [
              Shape {
                appearance PBRAppearance {
                  baseColor 0.75 0.75 0.75
                  roughness 1
                  metalness 0
                }
                geometry Mesh {
                  url [
                    "../meshes/Prop_ccw.obj"
                  ]
                }
              }
            ]
          }
        ]
        name "prop3ccw"
        boundingObject Pose {
          translation 0 0 0.0025
          children [
            Cylinder {
              height 0.005
              radius 0.055
            }
          ]
        }
        physics Physics {
          density -1
          mass 0.02
        }
      }
    }
    DEF prop2 HingeJoint {
      jointParameters HingeJointParameters {
        axis 0 0 -1
        anchor -0.1 0.1 0.047
      }
      device [
        RotationalMotor {
          name "motor 2"
          maxVelocity 100
        }
      ]
      endPoint Solid {
        translation -0.1 0.1 0.047
        rotation 0 0 -1 0
        children [
          Transform {
            scale 0.01 0.01 0.01
            children [
              Shape {
                appearance PBRAppearance {
                  baseColor 0.75 0.75 0.75
                  roughness 1
                  metalness 0
                }
                geometry Mesh {
                  url [
                    "../meshes/Prop_cw.obj"
                  ]
                }
              }
            ]
          }
        ]
        name "prop2cw"
        boundingObject Pose {
          translation 0 0 0.0025
          children [
            Cylinder {
              height 0.005
              radius 0.055
            }
          ]
        }
        physics Physics {
          density -1
          mass 0.02
        }
      }
    }
    DEF prop4 HingeJoint {
      jointParameters HingeJointParameters {
        axis 0 0 -1
        anchor 0.1 -0.1 0.047
      }
      device [
        RotationalMotor {
          name "motor 4"
          maxVelocity 100
        }
      ]
      endPoint Solid {
        translation 0.1 -0.1 0.047
        rotation 0 0 -1 0
        children [
          Transform {
            scale 0.01 0.01 0.01
            children [
              Shape {
                appearance PBRAppearance {
                  baseColor 0.75 0.75 0.75
                  roughness 1
                  metalness 0
                }
                geometry Mesh {
                  url [
                    "../meshes/Prop_cw.obj"
                  ]
                }
              }
            ]
          }
        ]
        name "prop4cw"
        boundingObject Pose {
          translation 0 0 0.0025
          children [
            Cylinder {
              height 0.005
              radius 0.055
            }
          ]
        }
        physics Physics {
          density -1
          mass 0.02
        }
      }
    }
  ]
  name "quadcopter"
  boundingObject Pose {
    translation 0 0 0.05
    children [
      Shape {
        geometry Box {
          size 0.24 0.24 0.1
        }
      }
    ]
  }
  physics Physics {
    density -1
    mass 0.5
    centerOfMass [
      0 0 0
    ]
    inertiaMatrix [
      0.0015 0.0015 0.0002
      0 0 0
    ]
  }
  controller "gps"
  supervisor TRUE
}
